Workbook
Name Slicer_New_MCR_ID: #N/A

Sheet BP2026_Archive (21Apr26)
A1: Team bucket | B1: New Team bucket | C1: New MCR ID | D1: WBS | E1: Task name | F1: Resource group | G1: Orga new | H1: Cost type | I1: Person booking | J1: BP26 FTE (%) - input | K1: Target Responsible | L1: CF02 FTE(%) - input | M1: Total Hrs 2026 | N1: Rate 2026 | O1: Personnel costs | P1: C-Hub PF | Q1: C-Hub Cust Ext | R1: CF02 C-Hub PF | S1: CF02 C-Hub Cust Ext | T1: CF05 C-Hub PF | U1: CF05 C-Hub Cust Ext | V1: Comments | W1: Act Jan-25 | X1: Act Feb-25 | Y1: Act Mar-25 | Z1: Act Apr-25 | AA1: Act May-25 | AB1: Act Jun-25 | AC1: Act Jul-25 | AD1: Act Aug-25 | AE1: Act Sep-25 | AF1: Act Oct-25 | AG1: Act Nov-25 | AH1: Act Dec-25 | AI1: YTD Actuals 2025 | AJ1: BAC (CF05 Plan) | AK1: EAC (based on YTD actuals) | AL1: Gap | AM1: Column1
A2: Refunding | B2: Refunding | C2: BM-00110021_003 | D2: BM-00110021_003_00000006 | E2: Refunding for C-Hub main project ögP | F2: PS-SC/CE-EU, CE-PE Publicly Funded Project - Refunding | H2: Refunding | I2: (blank) | P2: -330000 | Q2: 0 | R2: =Table42610[[#This Row],[C-Hub PF]] -> -330000 | T2: -330000 | AI2: =SUMIF(#REF!,"completed",Table42610[[#This Row],[Act Jan-25]:[Act Dec-25]]) -> #REF! | AJ2: =Table42610[[#This Row],[CF05 C-Hub PF]] -> -330000 | AK2: -330000 | AL2: =Table42610[[#This Row],[EAC (based on YTD actuals)]]-Table42610[[#This Row],[BAC (CF05 Plan)]] -> 0
A3: Stretch target | B3: Stretch target | C3: BM-00110021_002 | E3: Stretch target (budget cut) | F3: PS-SC/PAC Other Costs | H3: Stretch target | R3: -400000 | T3: -400000 | V3: Budget cut = 400k€, set initially on 27-Jan-26 in _003 | AI3: =SUMIF(#REF!,"completed",Table42610[[#This Row],[Act Jan-25]:[Act Dec-25]]) -> #REF! | AJ3: =Table42610[[#This Row],[CF05 C-Hub PF]] -> -400000 | AK3: =SUM(Table42610[[#This Row],[Act Jan-25]:[Act Dec-25]]) -> 0 | AL3: =Table42610[[#This Row],[EAC (based on YTD actuals)]]-Table42610[[#This Row],[BAC (CF05 Plan)]] -> 400000
A4: Refunding | B4: Refunding | C4: BM-00110021_005 | E4: Refunding for C-Hub XC ögP | F4: PS-SC/CE-EU, CE-PE Publicly Funded Project - Refunding | H4: Refunding | I4: (blank) | P4: 0 | Q4: 0 | R4: =Table42610[[#This Row],[C-Hub PF]] -> 0 | T4: 0 | Y4: =$AJ4/12 -> 0 | Z4: =$AJ4/12 -> 0 | AA4: =$AJ4/12 -> 0 | AB4: =$AJ4/12 -> 0 | AC4: =$AJ4/12 -> 0 | AD4: =$AJ4/12 -> 0 | AE4: =$AJ4/12 -> 0 | AF4: =$AJ4/12 -> 0 | ... AH4: =$AJ4/12 -> 0 | AI4: =SUMIF(#REF!,"completed",Table42610[[#This Row],[Act Jan-25]:[Act Dec-25]]) -> #REF! | AJ4: =Table42610[[#This Row],[CF05 C-Hub PF]] -> 0 | AK4: =SUM(Table42610[[#This Row],[Act Jan-25]:[Act Dec-25]]) -> 0 | AL4: =Table42610[[#This Row],[EAC (based on YTD actuals)]]-Table42610[[#This Row],[BAC (CF05 Plan)]] -> 0
A5: Customer specific effort | C5: BM-00110021_002 | E5: Customer integrations | F5: PS-SC/PAC Other Costs | G5: PA-CS | H5: Other cost | I5: assumtption: 10 customer á 80k€ | P5: 0 | Q5: 250000 | R5: =Table42610[[#This Row],[C-Hub PF]] -> 0 | S5: 250000 | T5: 0 | U5: 250000 | Y5: =$AJ5/12 -> 0 | Z5: =$AJ5/12 -> 0 | AA5: =$AJ5/12 -> 0 | AB5: =$AJ5/12 -> 0 | AC5: =$AJ5/12 -> 0 | AD5: =$AJ5/12 -> 0 | AE5: =$AJ5/12 -> 0 | AF5: =$AJ5/12 -> 0 | ... AH5: =$AJ5/12 -> 0 | AI5: =SUMIF(#REF!,"completed",Table42610[[#This Row],[Act Jan-25]:[Act Dec-25]]) -> #REF! | AJ5: =Table42610[[#This Row],[CF05 C-Hub PF]] -> 0 | AK5: =SUM(Table42610[[#This Row],[Act Jan-25]:[Act Dec-25]]) -> 0 | AL5: =Table42610[[#This Row],[EAC (based on YTD actuals)]]-Table42610[[#This Row],[BAC (CF05 Plan)]] -> 0
A6: Cojali Development | C6: BM-00110021_002 | D6: BM-00110021_002_00000005 | E6: MA for vehicle configuration | F6: PS-SC/PAC Other Costs | G6: ETAS | H6: Other cost | I6: Dirk needed for tranfer to PS | J6: 1 | P6: 202500 | Q6: 67500 | R6: 210000 | S6: 67500 | T6: 210000 | U6: 67500 | V6: PO #0087207184, C-Hub Content & Consultation Q1-Q3 2026 | X6: 21953.85 | Y6: 22181.16 | Z6: =$AJ6/9 -> 23333.333 | AA6: =$AJ6/9 -> 23333.333 | AB6: =$AJ6/9 -> 23333.333 | AC6: =$AJ6/9 -> 23333.333 | AD6: =$AJ6/9 -> 23333.333 | AE6: =$AJ6/9 -> 23333.333 | AI6: =SUMIF(#REF!,"completed",Table42610[[#This Row],[Act Jan-25]:[Act Dec-25]]) -> #REF! | AJ6: =Table42610[[#This Row],[CF05 C-Hub PF]] -> 210000 | AK6: =SUM(Table42610[[#This Row],[Act Jan-25]:[Act Dec-25]]) -> 184135.01 | AL6: =Table42610[[#This Row],[EAC (based on YTD actuals)]]-Table42610[[#This Row],[BAC (CF05 Plan)]] -> -25864.99
A7: Cojali Development | C7: BM-00110021_002 | E7: MA for vehicle configuration | F7: PS-SC/PAC Other Costs | G7: ETAS | H7: Manually added cost | V7: For Actual only, do not plan in MCR | W7: 21953.85 | Z7: =$AJ7/12 -> 0 | AA7: =$AJ7/12 -> 0 | AB7: =$AJ7/12 -> 0 | AC7: =$AJ7/12 -> 0 | AD7: =$AJ7/12 -> 0 | AE7: =$AJ7/12 -> 0 | AF7: =$AJ7/12 -> 0 | AG7: =$AJ7/12 -> 0 | AH7: =$AJ7/12 -> 0 | AI7: =SUMIF(#REF!,"completed",Table42610[[#This Row],[Act Jan-25]:[Act Dec-25]]) -> #REF! | AJ7: =Table42610[[#This Row],[CF05 C-Hub PF]] -> 0
A8: Cojali Development | C8: BM-00110021_002 | E8: RM+RD config + Cojali + Pantaris configs | F8: PS-SC/EDS_PS-SC EDS_PS-SC_XPS | G8: Cluj | H8: Personnel cost | I8: NN | J8: 1 | K8: Alkis | L8: 1 | M8: =_xlfn.IFNA(VLOOKUP(Table42610[[#This Row],[Resource group]],#REF!,2,FALSE),"0") -> #REF! | N8: =_xlfn.IFNA(VLOOKUP(Table42610[[#This Row],[Resource group]],#REF!,4,FALSE),"0") -> #REF! | O8: =Table42610[[#This Row],[BP26 FTE (%) - input]]*Table42610[[#This Row],[Total Hrs 2026]]*Table42610[[#This Row],[Rate 2026]] -> #REF! | P8: 78598.667 | Q8: 0 | R8: =Table42610[[#This Row],[CF02 FTE(%) - input]]*Table42610[[#This Row],[Total Hrs 2026]]*Table42610[[#This Row],[Rate 2026]] -> #REF! | T8: 78598.667 | V8: tbd w/ Alin: who is staffed here | Z8: =$AJ8/12 -> 6549.8889 | AA8: =$AJ8/12 -> 6549.8889 | AB8: =$AJ8/12 -> 6549.8889 | AC8: =$AJ8/12 -> 6549.8889 | AD8: =$AJ8/12 -> 6549.8889 | AE8: =$AJ8/12 -> 6549.8889 | AF8: =$AJ8/12 -> 6549.8889 | AG8: =$AJ8/12 -> 6549.8889 | AH8: =$AJ8/12 -> 6549.8889 | AI8: =SUMIF(#REF!,"completed",Table42610[[#This Row],[Act Jan-25]:[Act Dec-25]]) -> #REF! | AJ8: =Table42610[[#This Row],[CF05 C-Hub PF]] -> 78598.667 | AK8: =SUM(Table42610[[#This Row],[Act Jan-25]:[Act Dec-25]]) -> 58949 | AL8: =Table42610[[#This Row],[EAC (based on YTD actuals)]]-Table42610[[#This Row],[BAC (CF05 Plan)]] -> -19649.667
A9: Cojali Development | B9: Service Delivery OPS & Support | C9: BM-00110021_002 | E9: RM+RD config + Cojali + Pantaris configs | F9: MS/ECP-PS-IN_iGPM SW-Services_DP | G9: IN | H9: Personnel cost | I9: Dhingra, Manish | J9: 1 | K9: Ann/Alexander | L9: 1 | M9: =_xlfn.IFNA(VLOOKUP(Table42610[[#This Row],[Resource group]],#REF!,2,FALSE),"0") -> #REF! | N9: =_xlfn.IFNA(VLOOKUP(Table42610[[#This Row],[Resource group]],#REF!,4,FALSE),"0") -> #REF! | O9: =Table42610[[#This Row],[BP26 FTE (%) - input]]*Table42610[[#This Row],[Total Hrs 2026]]*Table42610[[#This Row],[Rate 2026]] -> #REF! | P9: 52462.84 | Q9: 0 | R9: =Table42610[[#This Row],[CF02 FTE(%) - input]]*Table42610[[#This Row],[Total Hrs 2026]]*Table42610[[#This Row],[Rate 2026]] -> #REF! | T9: 52462.84 | W9: 4166.1956 | X9: 4107.1233 | Y9: 4146.7853 | Z9: =$AJ9/12 -> 4371.9033 | AA9: =$AJ9/12 -> 4371.9033 | AB9: =$AJ9/12 -> 4371.9033 | AC9: =$AJ9/12 -> 4371.9033 | AD9: =$AJ9/12 -> 4371.9033 | AE9: =$AJ9/12 -> 4371.9033 | AF9: =$AJ9/12 -> 4371.9033 | AG9: =$AJ9/12 -> 4371.9033 | AH9: =$AJ9/12 -> 4371.9033 | AI9: =SUMIF(#REF!,"completed",Table42610[[#This Row],[Act Jan-25]:[Act Dec-25]]) -> #REF! | AJ9: =Table42610[[#This Row],[CF05 C-Hub PF]] -> 52462.84 | AK9: =SUM(Table42610[[#This Row],[Act Jan-25]:[Act Dec-25]]) -> 51767.234 | AL9: =Table42610[[#This Row],[EAC (based on YTD actuals)]]-Table42610[[#This Row],[BAC (CF05 Plan)]] -> -695.6058
A10: E2E C-Hub System Team | C10: BM-00110021_002 | E10: Data / rev. Eng. and AI | F10: PS-SC/PAC Other Costs | G10: PA-CS | H10: Other cost | I10: (blank) | J10: other cost | P10: 0 | Q10: 0 | R10: =Table42610[[#This Row],[C-Hub PF]] -> 0 | T10: 0 | Y10: =$AJ10/12 -> 0 | Z10: =$AJ10/12 -> 0 | AA10: =$AJ10/12 -> 0 | AB10: =$AJ10/12 -> 0 | AC10: =$AJ10/12 -> 0 | AD10: =$AJ10/12 -> 0 | AE10: =$AJ10/12 -> 0 | AF10: =$AJ10/12 -> 0 | ... AH10: =$AJ10/12 -> 0 | AI10: =SUMIF(#REF!,"completed",Table42610[[#This Row],[Act Jan-25]:[Act Dec-25]]) -> #REF! | AJ10: =Table42610[[#This Row],[CF05 C-Hub PF]] -> 0 | AK10: =SUM(Table42610[[#This Row],[Act Jan-25]:[Act Dec-25]])/COUNTIF(#REF!,"completed")*12 -> #REF! | AL10: =Table42610[[#This Row],[EAC (based on YTD actuals)]]-Table42610[[#This Row],[BAC (CF05 Plan)]] -> #REF!
A11: Other costs | C11: BM-00110021_002 | E11: Series Logistics Concept | F11: PS-SC/PAC Other Costs | G11: M | H11: Other cost | I11: (blank) | J11: other cost | P11: 0 | Q11: 0 | R11: =Table42610[[#This Row],[C-Hub PF]] -> 0 | T11: 0 | Y11: =$AJ11/12 -> 0 | Z11: =$AJ11/12 -> 0 | AA11: =$AJ11/12 -> 0 | AB11: =$AJ11/12 -> 0 | AC11: =$AJ11/12 -> 0 | AD11: =$AJ11/12 -> 0 | AE11: =$AJ11/12 -> 0 | AF11: =$AJ11/12 -> 0 | ... AH11: =$AJ11/12 -> 0 | AI11: =SUMIF(#REF!,"completed",Table42610[[#This Row],[Act Jan-25]:[Act Dec-25]]) -> #REF! | AJ11: =Table42610[[#This Row],[CF05 C-Hub PF]] -> 0 | AK11: =SUM(Table42610[[#This Row],[Act Jan-25]:[Act Dec-25]])/COUNTIF(#REF!,"completed")*12 -> #REF! | AL11: =Table42610[[#This Row],[EAC (based on YTD actuals)]]-Table42610[[#This Row],[BAC (CF05 Plan)]] -> #REF!
A12: NA Activities | B12: NA ENG Team | C12: BM-00110021_002 | E12: NA Team + other cost | F12: PS-SC/EBR-NA SW Eng | G12: PA-CS/NA | H12: Personnel cost | J12: 4 | L12: 2 | M12: =_xlfn.IFNA(VLOOKUP(Table42610[[#This Row],[Resource group]],#REF!,2,FALSE),"0") -> #REF! | N12: =_xlfn.IFNA(VLOOKUP(Table42610[[#This Row],[Resource group]],#REF!,4,FALSE),"0") -> #REF! | O12: =Table42610[[#This Row],[BP26 FTE (%) - input]]*Table42610[[#This Row],[Total Hrs 2026]]*Table42610[[#This Row],[Rate 2026]] -> #REF! | P12: 423141.91 | Q12: 423141.91 | R12: =Table42610[[#This Row],[CF02 FTE(%) - input]]*Table42610[[#This Row],[Total Hrs 2026]]*Table42610[[#This Row],[Rate 2026]] -> #REF! | S12: 423141.91 | T12: 423141.91 | U12: 423141.91 | Z12: =$AJ12/12 -> 35261.826 | AA12: =$AJ12/12 -> 35261.826 | AB12: =$AJ12/12 -> 35261.826 | AC12: =$AJ12/12 -> 35261.826 | AD12: =$AJ12/12 -> 35261.826 | AE12: =$AJ12/12 -> 35261.826 | AF12: =$AJ12/12 -> 35261.826 | AG12: =$AJ12/12 -> 35261.826 | AH12: =$AJ12/12 -> 35261.826 | AI12: =SUMIF(#REF!,"completed",Table42610[[#This Row],[Act Jan-25]:[Act Dec-25]]) -> #REF! | AJ12: =Table42610[[#This Row],[CF05 C-Hub PF]] -> 423141.91 | AK12: =SUM(W12:AH13) -> 423141.93 | AL12: =Table42610[[#This Row],[EAC (based on YTD actuals)]]-Table42610[[#This Row],[BAC (CF05 Plan)]] -> 0.014492754
A13: NA Activities | B13: NA ENG Team | C13: BM-00110021_002 | E13: NA Team + other cost | F13: PS-SC/EBR-NA SW Eng | G13: PA-CS/NA | H13: Manually added cost | W13: 35261.833 | X13: 35261.833 | Y13: 35261.826 | Z13: =$AJ13/12 -> 0 | AA13: =$AJ13/12 -> 0 | AB13: =$AJ13/12 -> 0 | AC13: =$AJ13/12 -> 0 | AD13: =$AJ13/12 -> 0 | AE13: =$AJ13/12 -> 0 | AF13: =$AJ13/12 -> 0 | AG13: =$AJ13/12 -> 0 | AH13: =$AJ13/12 -> 0 | AI13: =SUMIF(#REF!,"completed",Table42610[[#This Row],[Act Jan-25]:[Act Dec-25]]) -> #REF! | AJ13: =Table42610[[#This Row],[CF05 C-Hub PF]] -> 0 | AL13: =Table42610[[#This Row],[EAC (based on YTD actuals)]]-Table42610[[#This Row],[BAC (CF05 Plan)]] -> 0
A14: Cojali Development | C14: BM-00110021_002 | D14: BM-00110021_002_00000008 | E14: VCS SW maintance | F14: PS-SC/PAC Other Costs | G14: VCS | H14: Other cost | I14: (blank) | J14: Walter/Rainer klärt mit Daniel | P14: 370000 | Q14: 0 | R14: =Table42610[[#This Row],[C-Hub PF]] -> 370000 | T14: 370000 | V14: 27-Feb: Lates planning = 222 kEUR | Y14: 37000 | Z14: 18500 | AA14: 18500 | AB14: 18500 | AC14: 18500 | AD14: 18500 | AE14: 18500 | AF14: 18500 | AG14: 18500 | AH14: 18500 | AI14: =SUMIF(#REF!,"completed",Table42610[[#This Row],[Act Jan-25]:[Act Dec-25]]) -> #REF! | AJ14: =Table42610[[#This Row],[CF05 C-Hub PF]] -> 370000 | AK14: =SUM(W14:AH15) -> 222000 | AL14: =Table42610[[#This Row],[EAC (based on YTD actuals)]]-Table42610[[#This Row],[BAC (CF05 Plan)]] -> -148000
A15: Cojali Development | C15: BM-00110021_002 | E15: VCS SW maintance | F15: PS-SC/PAC Other Costs | G15: VCS | H15: Manually added cost | V15: For Actual only, do not plan in MCR | Y15: 18500 | Z15: =$AJ15/12 -> 0 | AA15: =$AJ15/12 -> 0 | AB15: =$AJ15/12 -> 0 | AC15: =$AJ15/12 -> 0 | AD15: =$AJ15/12 -> 0 | AE15: =$AJ15/12 -> 0 | AF15: =$AJ15/12 -> 0 | AG15: =$AJ15/12 -> 0 | AH15: =$AJ15/12 -> 0 | AI15: =SUMIF(#REF!,"completed",Table42610[[#This Row],[Act Jan-25]:[Act Dec-25]]) -> #REF! | AJ15: =Table42610[[#This Row],[CF05 C-Hub PF]] -> 0
A16: E2E C-Hub System Team | B16: Sys-Integration & Testing | C16: BM-00110021_003 | E16: System integration and performing V&V | F16: PS-SC/XPS PS-SC XPS development | G16: PA-CS | H16: Personnel cost | I16: Weiss Patrick (PS-SC/XPS) | J16: 1 | K16: Alkis | L16: 0.5 | M16: =_xlfn.IFNA(VLOOKUP(Table42610[[#This Row],[Resource group]],#REF!,2,FALSE),"0") -> #REF! | N16: =_xlfn.IFNA(VLOOKUP(Table42610[[#This Row],[Resource group]],#REF!,4,FALSE),"0") -> #REF! | O16: =Table42610[[#This Row],[BP26 FTE (%) - input]]*Table42610[[#This Row],[Total Hrs 2026]]*Table42610[[#This Row],[Rate 2026]] -> #REF! | P16: 124588.8 | Q16: 0 | R16: =Table42610[[#This Row],[CF02 FTE(%) - input]]*Table42610[[#This Row],[Total Hrs 2026]]*Table42610[[#This Row],[Rate 2026]] -> #REF! | T16: 124588.8 | Z16: =$AJ16/12 -> 10382.4 | AA16: =$AJ16/12 -> 10382.4 | AB16: =$AJ16/12 -> 10382.4 | AC16: =$AJ16/12 -> 10382.4 | AD16: =$AJ16/12 -> 10382.4 | AE16: =$AJ16/12 -> 10382.4 | AF16: =$AJ16/12 -> 10382.4 | AG16: =$AJ16/12 -> 10382.4 | AH16: =$AJ16/12 -> 10382.4 | AI16: =SUMIF(#REF!,"completed",Table42610[[#This Row],[Act Jan-25]:[Act Dec-25]]) -> #REF! | AJ16: =Table42610[[#This Row],[CF05 C-Hub PF]] -> 124588.8 | AK16: =SUM(Table42610[[#This Row],[Act Jan-25]:[Act Dec-25]]) -> 93441.6 | AL16: =Table42610[[#This Row],[EAC (based on YTD actuals)]]-Table42610[[#This Row],[BAC (CF05 Plan)]] -> -31147.2
A17: PjM, Biz Dev, service mng | B17: Service Delivery OPS & Support | C17: BM-00110021_002 | E17: Operations L1/L2 Incident/Problem/Monitoring | F17: PS-SC/EDS_PS-SC EDS_PS-SC_XPS | G17: Cluj | H17: Personnel cost | I17: Sorina (support) + Bianca + Maria (200%) | J17: 2 | K17: Ann | L17: 1.5 | M17: =_xlfn.IFNA(VLOOKUP(Table42610[[#This Row],[Resource group]],#REF!,2,FALSE),"0") -> #REF! | N17: =_xlfn.IFNA(VLOOKUP(Table42610[[#This Row],[Resource group]],#REF!,4,FALSE),"0") -> #REF! | O17: =Table42610[[#This Row],[BP26 FTE (%) - input]]*Table42610[[#This Row],[Total Hrs 2026]]*Table42610[[#This Row],[Rate 2026]] -> #REF! | P17: 117898 | Q17: 78598.667 | R17: =Table42610[[#This Row],[CF02 FTE(%) - input]]*Table42610[[#This Row],[Total Hrs 2026]]*Table42610[[#This Row],[Rate 2026]] -> #REF! | S17: =Table42610[[#This Row],[CF02 C-Hub PF]]/3*2 -> #REF! | T17: 117898 | U17: 78598.667 | V17: tbd w/ Alin: is that working out | W17: 6137.136 | X17: 14303.653 | Y17: 6939.0464 | Z17: =$AJ17/12 -> 9824.8333 | AA17: =$AJ17/12 -> 9824.8333 | AB17: =$AJ17/12 -> 9824.8333 | AC17: =$AJ17/12 -> 9824.8333 | AD17: =$AJ17/12 -> 9824.8333 | AE17: =$AJ17/12 -> 9824.8333 | AF17: =$AJ17/12 -> 9824.8333 | AG17: =$AJ17/12 -> 9824.8333 | AH17: =$AJ17/12 -> 9824.8333 | AI17: =SUMIF(#REF!,"completed",Table42610[[#This Row],[Act Jan-25]:[Act Dec-25]]) -> #REF! | AJ17: =Table42610[[#This Row],[CF05 C-Hub PF]] -> 117898 | AK17: =SUM(Table42610[[#This Row],[Act Jan-25]:[Act Dec-25]]) -> 115803.34 | AL17: =Table42610[[#This Row],[EAC (based on YTD actuals)]]-Table42610[[#This Row],[BAC (CF05 Plan)]] -> -2094.6645
A18: PjM, Biz Dev, service mng | B18: Service Delivery OPS & Support | C18: BM-00110021_002 | E18: Service Management | F18: PS-SC/ETX | G18: Cluj | H18: Personnel cost | I18: Lausch, Ann Kathrin / Cluj PS-SC/ETX | J18: 1 | K18: Rainer | L18: 1 | M18: =_xlfn.IFNA(VLOOKUP(Table42610[[#This Row],[Resource group]],#REF!,2,FALSE),"0") -> #REF! | N18: =_xlfn.IFNA(VLOOKUP(Table42610[[#This Row],[Resource group]],#REF!,4,FALSE),"0") -> #REF! | O18: =Table42610[[#This Row],[BP26 FTE (%) - input]]*Table42610[[#This Row],[Total Hrs 2026]]*Table42610[[#This Row],[Rate 2026]] -> #REF! | P18: 81435.784 | Q18: 0 | R18: =Table42610[[#This Row],[CF02 FTE(%) - input]]*Table42610[[#This Row],[Total Hrs 2026]]*Table42610[[#This Row],[Rate 2026]] -> #REF! | T18: 81435.784 | W18: 7684.7616 | X18: 8165.8915 | Y18: =$AJ18/12 -> 6786.3154 | Z18: =$AJ18/12 -> 6786.3154 | AA18: =$AJ18/12 -> 6786.3154 | AB18: =$AJ18/12 -> 6786.3154 | AC18: =$AJ18/12 -> 6786.3154 | AD18: =$AJ18/12 -> 6786.3154 | AE18: =$AJ18/12 -> 6786.3154 | AF18: =$AJ18/12 -> 6786.3154 | ... AH18: =$AJ18/12 -> 6786.3154 | AI18: =SUMIF(#REF!,"completed",Table42610[[#This Row],[Act Jan-25]:[Act Dec-25]]) -> #REF! | AJ18: =Table42610[[#This Row],[CF05 C-Hub PF]] -> 81435.784 | AK18: =SUM(Table42610[[#This Row],[Act Jan-25]:[Act Dec-25]]) -> 83713.807 | AL18: =Table42610[[#This Row],[EAC (based on YTD actuals)]]-Table42610[[#This Row],[BAC (CF05 Plan)]] -> 2278.0224
A19: OPS Team EU (VI) | C19: BM-00110021_002 | D19: BM-00110021_002_00000009 | E19: Service Operation EU - VI | F19: PS-SC/PAC Other Costs | G19: Operation | H19: Other cost? | J19: to be aligned with Gernot | P19: 50000 | Q19: 75000 | R19: 25000 | S19: 100000 | T19: 25000 | U19: 100000 | Z19: =$AJ19/12 -> 2083.3333 | AA19: =$AJ19/12 -> 2083.3333 | AB19: =$AJ19/12 -> 2083.3333 | AC19: =$AJ19/12 -> 2083.3333 | AD19: =$AJ19/12 -> 2083.3333 | AE19: =$AJ19/12 -> 2083.3333 | AF19: =$AJ19/12 -> 2083.3333 | AG19: =$AJ19/12 -> 2083.3333 | AH19: =$AJ19/12 -> 2083.3333 | AI19: =SUMIF(#REF!,"completed",Table42610[[#This Row],[Act Jan-25]:[Act Dec-25]]) -> #REF! | AJ19: =Table42610[[#This Row],[CF05 C-Hub PF]] -> 25000 | AK19: =SUM(Table42610[[#This Row],[Act Jan-25]:[Act Dec-25]]) -> 18750 | AL19: =Table42610[[#This Row],[EAC (based on YTD actuals)]]-Table42610[[#This Row],[BAC (CF05 Plan)]] -> -6250
A20: OPS Team NA (VI) | C20: BM-00110021_002 | D20: BM-00110021_002_00000010 | E20: Service Operation NA - VI | F20: PS-SC/PAC Other Costs | G20: Operation | H20: Other cost? | J20: to be aligned with Gernot | P20: 50000 | Q20: 75000 | R20: 25000 | S20: 100000 | T20: 25000 | U20: 100000 | Z20: =$AJ20/12 -> 2083.3333 | AA20: =$AJ20/12 -> 2083.3333 | AB20: =$AJ20/12 -> 2083.3333 | AC20: =$AJ20/12 -> 2083.3333 | AD20: =$AJ20/12 -> 2083.3333 | AE20: =$AJ20/12 -> 2083.3333 | AF20: =$AJ20/12 -> 2083.3333 | AG20: =$AJ20/12 -> 2083.3333 | AH20: =$AJ20/12 -> 2083.3333 | AI20: =SUMIF(#REF!,"completed",Table42610[[#This Row],[Act Jan-25]:[Act Dec-25]]) -> #REF! | AJ20: =Table42610[[#This Row],[CF05 C-Hub PF]] -> 25000 | AK20: =SUM(Table42610[[#This Row],[Act Jan-25]:[Act Dec-25]]) -> 18750 | AL20: =Table42610[[#This Row],[EAC (based on YTD actuals)]]-Table42610[[#This Row],[BAC (CF05 Plan)]] -> -6250
A21: PjM, Biz Dev, service mng | B21: Partner Management | C21: BM-00110021_003 | E21: Partner Manager | F21: PS-SC/PAC PAC1 | G21: PA-CS | H21: Personnel cost | I21: Hornung, Floyd? | J21: 1 | L21: 0.2 | M21: =_xlfn.IFNA(VLOOKUP(Table42610[[#This Row],[Resource group]],#REF!,2,FALSE),"0") -> #REF! | N21: =_xlfn.IFNA(VLOOKUP(Table42610[[#This Row],[Resource group]],#REF!,4,FALSE),"0") -> #REF! | O21: =Table42610[[#This Row],[BP26 FTE (%) - input]]*Table42610[[#This Row],[Total Hrs 2026]]*Table42610[[#This Row],[Rate 2026]] -> #REF! | P21: 42144.3 | Q21: 63216.45 | R21: 0 | T21: 0 | Z21: =$AJ21/12 -> 0 | AA21: =$AJ21/12 -> 0 | AB21: =$AJ21/12 -> 0 | AC21: =$AJ21/12 -> 0 | AD21: =$AJ21/12 -> 0 | AE21: =$AJ21/12 -> 0 | AF21: =$AJ21/12 -> 0 | AG21: =$AJ21/12 -> 0 | AH21: =$AJ21/12 -> 0 | AI21: =SUMIF(#REF!,"completed",Table42610[[#This Row],[Act Jan-25]:[Act Dec-25]]) -> #REF! | AJ21: =Table42610[[#This Row],[CF05 C-Hub PF]] -> 0 | AK21: =SUM(Table42610[[#This Row],[Act Jan-25]:[Act Dec-25]])/COUNTIF(#REF!,"completed")*12 -> #REF! | AL21: =Table42610[[#This Row],[EAC (based on YTD actuals)]]-Table42610[[#This Row],[BAC (CF05 Plan)]] -> #REF!
A22: PjM, Biz Dev, service mng | B22: Partner Management | C22: BM-00110021_002 | E22: Partner Manager | F22: PS-SC/ETX | G22: Cluj | H22: Personnel cost | I22: Ciolte Natalia Liliana (PS-SC/ETX1) | K22: Rainer | L22: 0.5 | M22: =_xlfn.IFNA(VLOOKUP(Table42610[[#This Row],[Resource group]],#REF!,2,FALSE),"0") -> #REF! | N22: =_xlfn.IFNA(VLOOKUP(Table42610[[#This Row],[Resource group]],#REF!,4,FALSE),"0") -> #REF! | O22: =Table42610[[#This Row],[BP26 FTE (%) - input]]*Table42610[[#This Row],[Total Hrs 2026]]*Table42610[[#This Row],[Rate 2026]] -> #REF! | R22: =Table42610[[#This Row],[CF02 FTE(%) - input]]*Table42610[[#This Row],[Total Hrs 2026]]*Table42610[[#This Row],[Rate 2026]] -> #REF! | S22: =Table42610[[#This Row],[CF02 C-Hub PF]] -> #REF! | T22: 40717.892 | U22: 40717.892 | W22: 3201.984 | X22: 4056.2598 | Y22: 4590.4461 | Z22: =$AJ22/12 -> 3393.1577 | AA22: =$AJ22/12 -> 3393.1577 | AB22: =$AJ22/12 -> 3393.1577 | AC22: =$AJ22/12 -> 3393.1577 | AD22: =$AJ22/12 -> 3393.1577 | AE22: =$AJ22/12 -> 3393.1577 | AF22: =$AJ22/12 -> 3393.1577 | AG22: =$AJ22/12 -> 3393.1577 | AH22: =$AJ22/12 -> 3393.1577 | AI22: =SUMIF(#REF!,"completed",Table42610[[#This Row],[Act Jan-25]:[Act Dec-25]]) -> #REF! | AJ22: =Table42610[[#This Row],[CF05 C-Hub PF]] -> 40717.892 | AK22: =SUM(Table42610[[#This Row],[Act Jan-25]:[Act Dec-25]]) -> 42387.109 | AL22: =Table42610[[#This Row],[EAC (based on YTD actuals)]]-Table42610[[#This Row],[BAC (CF05 Plan)]] -> 1669.2169
A23: Cojali Development | B23: Supporting Functions | C23: BM-00110021_002 | E23: EPQ | F23: MS/ECP-PS-IN_iGPM SW-Services_DP | G23: IN | H23: Personnel cost | I23: Lakshmi, Ramakrishnan | J23: 0.35 | L23: 0.5 | M23: =_xlfn.IFNA(VLOOKUP(Table42610[[#This Row],[Resource group]],#REF!,2,FALSE),"0") -> #REF! | N23: =_xlfn.IFNA(VLOOKUP(Table42610[[#This Row],[Resource group]],#REF!,4,FALSE),"0") -> #REF! | O23: =Table42610[[#This Row],[BP26 FTE (%) - input]]*Table42610[[#This Row],[Total Hrs 2026]]*Table42610[[#This Row],[Rate 2026]] -> #REF! | P23: 18361.994 | Q23: 0 | R23: =Table42610[[#This Row],[CF02 FTE(%) - input]]*Table42610[[#This Row],[Total Hrs 2026]]*Table42610[[#This Row],[Rate 2026]] -> #REF! | T23: 26231.42 | W23: 1602.3829 | X23: 1842.9399 | Y23: 1860.737 | Z23: =$AJ23/12 -> 2185.9517 | AA23: =$AJ23/12 -> 2185.9517 | AB23: =$AJ23/12 -> 2185.9517 | AC23: =$AJ23/12 -> 2185.9517 | AD23: =$AJ23/12 -> 2185.9517 | AE23: =$AJ23/12 -> 2185.9517 | AF23: =$AJ23/12 -> 2185.9517 | AG23: =$AJ23/12 -> 2185.9517 | AH23: =$AJ23/12 -> 2185.9517 | AI23: =SUMIF(#REF!,"completed",Table42610[[#This Row],[Act Jan-25]:[Act Dec-25]]) -> #REF! | AJ23: =Table42610[[#This Row],[CF05 C-Hub PF]] -> 26231.42 | AK23: =SUM(Table42610[[#This Row],[Act Jan-25]:[Act Dec-25]]) -> 24979.625 | AL23: =Table42610[[#This Row],[EAC (based on YTD actuals)]]-Table42610[[#This Row],[BAC (CF05 Plan)]] -> -1251.7951
A24: Cojali Development | B24: Supporting Functions | C24: BM-00110021_002 | E24: Security Manager | F24: PS-SC/EDS_PS-SC EDS_PS-SC_XPS | G24: IN | H24: Personnel cost | I24: Covasa Szilard Fineas (PS-SC/EDS1) | J24: 0.25 | K24: Lakshmi | L24: 0.25 | M24: =_xlfn.IFNA(VLOOKUP(Table42610[[#This Row],[Resource group]],#REF!,2,FALSE),"0") -> #REF! | N24: =_xlfn.IFNA(VLOOKUP(Table42610[[#This Row],[Resource group]],#REF!,4,FALSE),"0") -> #REF! | O24: =Table42610[[#This Row],[BP26 FTE (%) - input]]*Table42610[[#This Row],[Total Hrs 2026]]*Table42610[[#This Row],[Rate 2026]] -> #REF! | P24: 19649.667 | Q24: 0 | R24: =Table42610[[#This Row],[CF02 FTE(%) - input]]*Table42610[[#This Row],[Total Hrs 2026]]*Table42610[[#This Row],[Rate 2026]] -> #REF! | T24: 19649.667 | W24: 1387.5264 | X24: 7472.0576 | Y24: 5871.5008 | Z24: =$AJ24/12 -> 1637.4722 | AA24: =$AJ24/12 -> 1637.4722 | AB24: =$AJ24/12 -> 1637.4722 | AC24: =$AJ24/12 -> 1637.4722 | AD24: =$AJ24/12 -> 1637.4722 | AE24: =$AJ24/12 -> 1637.4722 | AF24: =$AJ24/12 -> 1637.4722 | AG24: =$AJ24/12 -> 1637.4722 | AH24: =$AJ24/12 -> 1637.4722 | AI24: =SUMIF(#REF!,"completed",Table42610[[#This Row],[Act Jan-25]:[Act Dec-25]]) -> #REF! | AJ24: =Table42610[[#This Row],[CF05 C-Hub PF]] -> 19649.667 | AK24: =SUM(Table42610[[#This Row],[Act Jan-25]:[Act Dec-25]]) -> 29468.335 | AL24: =Table42610[[#This Row],[EAC (based on YTD actuals)]]-Table42610[[#This Row],[BAC (CF05 Plan)]] -> 9818.6681
A25: Cojali Development | B25: Supporting Functions | C25: BM-00110021_002 | E25: Support BGSW (Arun) | F25: MS/END-IN_iGPM Mechanical_Design_Services_W/O_CAD_SW_PS_Sensors | G25: IN | H25: Personnel cost | I25: Palanisamy, Babu | J25: 0.5 | L25: 0.5 | M25: =_xlfn.IFNA(VLOOKUP(Table42610[[#This Row],[Resource group]],#REF!,2,FALSE),"0") -> #REF! | N25: =_xlfn.IFNA(VLOOKUP(Table42610[[#This Row],[Resource group]],#REF!,4,FALSE),"0") -> #REF! | O25: =Table42610[[#This Row],[BP26 FTE (%) - input]]*Table42610[[#This Row],[Total Hrs 2026]]*Table42610[[#This Row],[Rate 2026]] -> #REF! | P25: 19721.52 | Q25: 0 | R25: =Table42610[[#This Row],[CF02 FTE(%) - input]]*Table42610[[#This Row],[Total Hrs 2026]]*Table42610[[#This Row],[Rate 2026]] -> #REF! | T25: 19721.52 | W25: 1574.6042 | X25: 1552.2779 | Y25: 1567.2681 | Z25: =$AJ25/12 -> 1643.46 | AA25: =$AJ25/12 -> 1643.46 | AB25: =$AJ25/12 -> 1643.46 | AC25: =$AJ25/12 -> 1643.46 | AD25: =$AJ25/12 -> 1643.46 | AE25: =$AJ25/12 -> 1643.46 | AF25: =$AJ25/12 -> 1643.46 | AG25: =$AJ25/12 -> 1643.46 | AH25: =$AJ25/12 -> 1643.46 | AI25: =SUMIF(#REF!,"completed",Table42610[[#This Row],[Act Jan-25]:[Act Dec-25]]) -> #REF! | AJ25: =Table42610[[#This Row],[CF05 C-Hub PF]] -> 19721.52 | AK25: =SUM(Table42610[[#This Row],[Act Jan-25]:[Act Dec-25]]) -> 19485.29 | AL25: =Table42610[[#This Row],[EAC (based on YTD actuals)]]-Table42610[[#This Row],[BAC (CF05 Plan)]] -> -236.22972
A26: E2E C-Hub System Team | B26: Sys-Integration & Testing | C26: BM-00110021_002 | D26: BM-00110021_002_00000011 | E26: BD Support (Technical Documentation) | F26: PS-SC/PAC Other Costs | G26: BD | H26: Other cost | I26: Marianne | J26: same as 2025 | P26: 87000 | Q26: 0 | R26: =Table42610[[#This Row],[C-Hub PF]] -> 87000 | T26: 0 | V26: CF05: BD costs aggregated to BM-00110021_002_00000012 | Y26: =$AJ26/12 -> 0 | Z26: =$AJ26/12 -> 0 | AA26: =$AJ26/12 -> 0 | AB26: =$AJ26/12 -> 0 | AC26: =$AJ26/12 -> 0 | AD26: =$AJ26/12 -> 0 | AE26: =$AJ26/12 -> 0 | AF26: =$AJ26/12 -> 0 | ... AH26: =$AJ26/12 -> 0 | AI26: =SUMIF(#REF!,"completed",Table42610[[#This Row],[Act Jan-25]:[Act Dec-25]]) -> #REF! | AJ26: =Table42610[[#This Row],[CF05 C-Hub PF]] -> 0 | AK26: =SUM(W26:AH27) -> 0 | AL26: =Table42610[[#This Row],[EAC (based on YTD actuals)]]-Table42610[[#This Row],[BAC (CF05 Plan)]] -> 0
A27: E2E C-Hub System Team | B27: Sys-Integration & Testing | C27: BM-00110021_002 | E27: BD Support (Technical Documentation) | F27: PS-SC/PAC Other Costs | G27: BD | H27: Manually added cost | V27: For Actual only, do not plan in MCR | Y27: =$AJ27/12 -> 0 | Z27: =$AJ27/12 -> 0 | AA27: =$AJ27/12 -> 0 | AB27: =$AJ27/12 -> 0 | AC27: =$AJ27/12 -> 0 | AD27: =$AJ27/12 -> 0 | AE27: =$AJ27/12 -> 0 | AF27: =$AJ27/12 -> 0 | ... AH27: =$AJ27/12 -> 0 | AI27: =SUMIF(#REF!,"completed",Table42610[[#This Row],[Act Jan-25]:[Act Dec-25]]) -> #REF! | AJ27: =Table42610[[#This Row],[CF05 C-Hub PF]] -> 0
A28: E2E C-Hub System Team | B28: Sys-Integration & Testing | C28: BM-00110021_003 | E28: Product development lead | F28: PS-CV/EES System Engineer EES (ex CVO/ENP) | G28: CV | H28: Personnel cost | I28: Hodzic, Alkis -> Transfer Alkis to PS-S -> C reduces costs | J28: 1 | L28: 1 | M28: =_xlfn.IFNA(VLOOKUP(Table42610[[#This Row],[Resource group]],#REF!,2,FALSE),"0") -> #REF! | N28: =_xlfn.IFNA(VLOOKUP(Table42610[[#This Row],[Resource group]],#REF!,4,FALSE),"0") -> #REF! | O28: =Table42610[[#This Row],[BP26 FTE (%) - input]]*Table42610[[#This Row],[Total Hrs 2026]]*Table42610[[#This Row],[Rate 2026]] -> #REF! | P28: 226865.1 | Q28: 0 | R28: =Table42610[[#This Row],[CF02 FTE(%) - input]]*Table42610[[#This Row],[Total Hrs 2026]]*Table42610[[#This Row],[Rate 2026]] -> #REF! | T28: 226865.1 | W28: 14975.622 | X28: 23139.679 | Y28: 21045 | Z28: =$AJ28/12 -> 18905.425 | AA28: =$AJ28/12 -> 18905.425 | AB28: =$AJ28/12 -> 18905.425 | AC28: =$AJ28/12 -> 18905.425 | AD28: =$AJ28/12 -> 18905.425 | AE28: =$AJ28/12 -> 18905.425 | AF28: =$AJ28/12 -> 18905.425 | AG28: =$AJ28/12 -> 18905.425 | AH28: =$AJ28/12 -> 18905.425 | AI28: =SUMIF(#REF!,"completed",Table42610[[#This Row],[Act Jan-25]:[Act Dec-25]]) -> #REF! | AJ28: =Table42610[[#This Row],[CF05 C-Hub PF]] -> 226865.1 | AK28: =SUM(Table42610[[#This Row],[Act Jan-25]:[Act Dec-25]]) -> 229309.13 | AL28: =Table42610[[#This Row],[EAC (based on YTD actuals)]]-Table42610[[#This Row],[BAC (CF05 Plan)]] -> 2444.026
A29: PjM, Biz Dev, service mng | C29: BM-00110021_002 | D29: BM-00110021_002_00000012 | E29: BD Support (PjM and Controlling) | F29: PS-SC/PAC Other Costs | G29: BD | H29: Other cost | I29: Rainer, Stan | J29: other cost | P29: 355125 | Q29: 0 | R29: =Table42610[[#This Row],[C-Hub PF]] -> 355125 | T29: 578153.67 | V29: CF05: BD costs aggregated to BM-00110021_002_00000012 | Y29: 183000 | Z29: =$AJ29/12 -> 48179.473 | AA29: =$AJ29/12 -> 48179.473 | AB29: =$AJ29/12 -> 48179.473 | AC29: =$AJ29/12 -> 48179.473 | AD29: =$AJ29/12 -> 48179.473 | AE29: =$AJ29/12 -> 48179.473 | AF29: =$AJ29/12 -> 48179.473 | AG29: =$AJ29/12 -> 48179.473 | AH29: =$AJ29/12-38462 -> 9717.4727 | AI29: =SUMIF(#REF!,"completed",Table42610[[#This Row],[Act Jan-25]:[Act Dec-25]]) -> #REF! | AJ29: =Table42610[[#This Row],[CF05 C-Hub PF]] -> 578153.67 | AK29: =SUM(W29:AH30) -> 578153.25 | AL29: =Table42610[[#This Row],[EAC (based on YTD actuals)]]-Table42610[[#This Row],[BAC (CF05 Plan)]] -> -0.418
A30: PjM, Biz Dev, service mng | C30: BM-00110021_002 | E30: BD Support (PjM and Controlling) | F30: PS-SC/PAC Other Costs | G30: BD | H30: Manually added cost | V30: For Actual only, do not plan in MCR | Y30: =$AJ30/12 -> 0 | Z30: =$AJ30/12 -> 0 | AA30: =$AJ30/12 -> 0 | AB30: =$AJ30/12 -> 0 | AC30: =$AJ30/12 -> 0 | AD30: =$AJ30/12 -> 0 | AE30: =$AJ30/12 -> 0 | AF30: =$AJ30/12 -> 0 | ... AH30: =$AJ30/12 -> 0 | AI30: =SUMIF(#REF!,"completed",Table42610[[#This Row],[Act Jan-25]:[Act Dec-25]]) -> #REF! | AJ30: =Table42610[[#This Row],[CF05 C-Hub PF]] -> 0
A31: XC-CP | B31: HW & BSW | C31: BM-00110021_004 | E31: C-Hub XC Series Care_004 | F31: Various XC | G31: XC | H31: Other cost | I31: Multiple | P31: 940241.92 | Q31: 0 | R31: 1052369.3 | T31: 1095000 | V31: CF05: ~ 43k€ increase (from 1052 to 1095 k€), input Can Oezcan | W31: 51609.372 | X31: 52372.822 | Y31: 50179.835 | Z31: =$AJ31/12 -> 91250 | AA31: =$AJ31/12 -> 91250 | AB31: =$AJ31/12 -> 91250 | AC31: =$AJ31/12 -> 91250 | AD31: =$AJ31/12 -> 91250 | AE31: =$AJ31/12 -> 91250 | AF31: =$AJ31/12 -> 91250 | AG31: =$AJ31/12 -> 91250 | AH31: =$AJ31/12 -> 91250 | AI31: =SUMIF(#REF!,"completed",Table42610[[#This Row],[Act Jan-25]:[Act Dec-25]]) -> #REF! | AJ31: =Table42610[[#This Row],[CF05 C-Hub PF]] -> 1095000 | AK31: =SUM(Table42610[[#This Row],[Act Jan-25]:[Act Dec-25]]) -> 975412.03 | AL31: =Table42610[[#This Row],[EAC (based on YTD actuals)]]-Table42610[[#This Row],[BAC (CF05 Plan)]] -> -119587.97
A32: XC-CP | B32: HW & BSW | C32: BM-00110021_005 | E32: C-Hub XC Series Care_005 | F32: Various XC | G32: XC | H32: Other cost | I32: Multiple | P32: 711127 | Q32: 0 | R32: 597620.65 | T32: 611000 | V32: CF05: ~13 k€ increase (from 598 to 611 k€), input Can Oezcan | W32: 35381.831 | X32: 39735.227 | Y32: 36237.213 | Z32: =$AJ32/12 -> 50916.667 | AA32: =$AJ32/12 -> 50916.667 | AB32: =$AJ32/12 -> 50916.667 | AC32: =$AJ32/12 -> 50916.667 | AD32: =$AJ32/12 -> 50916.667 | AE32: =$AJ32/12 -> 50916.667 | AF32: =$AJ32/12 -> 50916.667 | AG32: =$AJ32/12 -> 50916.667 | AH32: =$AJ32/12 -> 50916.667 | AI32: =SUMIF(#REF!,"completed",Table42610[[#This Row],[Act Jan-25]:[Act Dec-25]]) -> #REF! | AJ32: =Table42610[[#This Row],[CF05 C-Hub PF]] -> 611000 | AK32: =SUM(Table42610[[#This Row],[Act Jan-25]:[Act Dec-25]]) -> 569604.27 | AL32: =Table42610[[#This Row],[EAC (based on YTD actuals)]]-Table42610[[#This Row],[BAC (CF05 Plan)]] -> -41395.729
A33: XC-CP | B33: HW & BSW | C33: BM-00110021_004 | E33: C-Hub XC New Features | F33: Various XC | G33: XC | H33: Other cost | I33: Multiple | P33: 0 | Q33: 286993.92 | R33: =Table42610[[#This Row],[C-Hub PF]] -> 0 | S33: 286994 | T33: 0 | U33: 343003.95 | V33: CF05: Increased due to XC Stretch target increase | Y33: =$AJ33/12 -> 0 | Z33: =$AJ33/12 -> 0 | AA33: =$AJ33/12 -> 0 | AB33: =$AJ33/12 -> 0 | AC33: =$AJ33/12 -> 0 | AD33: =$AJ33/12 -> 0 | AE33: =$AJ33/12 -> 0 | AF33: =$AJ33/12 -> 0 | ... AH33: =$AJ33/12 -> 0 | AI33: =SUMIF(#REF!,"completed",Table42610[[#This Row],[Act Jan-25]:[Act Dec-25]]) -> #REF! | AJ33: =Table42610[[#This Row],[CF05 C-Hub PF]] -> 0 | AK33: =SUM(Table42610[[#This Row],[Act Jan-25]:[Act Dec-25]]) -> 0 | AL33: =Table42610[[#This Row],[EAC (based on YTD actuals)]]-Table42610[[#This Row],[BAC (CF05 Plan)]] -> 0
A34: XC-CP | B34: HW & BSW | C34: BM-00110021_005 | E34: C-Hub XC New Features | F34: Various XC | G34: XC | H34: Other cost | I34: Multiple | P34: 0 | Q34: 0 | R34: =Table42610[[#This Row],[C-Hub PF]] -> 0 | T34: 0 | Y34: =$AJ34/12 -> 0 | Z34: =$AJ34/12 -> 0 | AA34: =$AJ34/12 -> 0 | AB34: =$AJ34/12 -> 0 | AC34: =$AJ34/12 -> 0 | AD34: =$AJ34/12 -> 0 | AE34: =$AJ34/12 -> 0 | AF34: =$AJ34/12 -> 0 | ... AH34: =$AJ34/12 -> 0 | AI34: =SUMIF(#REF!,"completed",Table42610[[#This Row],[Act Jan-25]:[Act Dec-25]]) -> #REF! | AJ34: =Table42610[[#This Row],[CF05 C-Hub PF]] -> 0 | AK34: =SUM(Table42610[[#This Row],[Act Jan-25]:[Act Dec-25]]) -> 0 | AL34: =Table42610[[#This Row],[EAC (based on YTD actuals)]]-Table42610[[#This Row],[BAC (CF05 Plan)]] -> 0
A35: Cojali Development | C35: BM-00110021_002 | D35: BM-00110021_002_00000013 | E35: CVIT Partner Manager | F35: PS-SC/PAC Other Costs | G35: Bari | H35: Other cost | I35: (blank) | J35: 1 | P35: 98689.339 | R35: =Table42610[[#This Row],[C-Hub PF]] -> 98689.339 | T35: 98689.339 | Z35: =$AJ35/12 -> 8224.1116 | AA35: =$AJ35/12 -> 8224.1116 | AB35: =$AJ35/12 -> 8224.1116 | AC35: =$AJ35/12 -> 8224.1116 | AD35: =$AJ35/12 -> 8224.1116 | AE35: =$AJ35/12 -> 8224.1116 | AF35: =$AJ35/12 -> 8224.1116 | AG35: =$AJ35/12 -> 8224.1116 | AH35: =$AJ35/12 -> 8224.1116 | AI35: =SUMIF(#REF!,"completed",Table42610[[#This Row],[Act Jan-25]:[Act Dec-25]]) -> #REF! | AJ35: =Table42610[[#This Row],[CF05 C-Hub PF]] -> 98689.339 | AK35: =SUM(W35:AH36) -> 98689.339 | AL35: =Table42610[[#This Row],[EAC (based on YTD actuals)]]-Table42610[[#This Row],[BAC (CF05 Plan)]] -> 0
A36: Cojali Development | C36: BM-00110021_002 | E36: CVIT Partner Manager | F36: PS-SC/PAC Other Costs | H36: Manually added cost | V36: For Actual only, do not plan in MCR | W36: 8224.1116 | X36: 8224.1116 | Y36: 8224.1116 | Z36: =$AJ36/12 -> 0 | AA36: =$AJ36/12 -> 0 | AB36: =$AJ36/12 -> 0 | AC36: =$AJ36/12 -> 0 | AD36: =$AJ36/12 -> 0 | AE36: =$AJ36/12 -> 0 | AF36: =$AJ36/12 -> 0 | AG36: =$AJ36/12 -> 0 | AH36: =$AJ36/12 -> 0 | AI36: =SUMIF(#REF!,"completed",Table42610[[#This Row],[Act Jan-25]:[Act Dec-25]]) -> #REF! | AJ36: =Table42610[[#This Row],[CF05 C-Hub PF]] -> 0 | AL36: =Table42610[[#This Row],[EAC (based on YTD actuals)]]-Table42610[[#This Row],[BAC (CF05 Plan)]] -> 0
A37: Cojali Development | C37: BM-00110021_002 | D37: BM-00110021_002_00000014 | E37: ETAS-MSS Cojali | F37: PS-SC/PAC Other Costs | G37: ETAS | H37: Other cost | I37: (blank) | P37: 80000 | Q37: 70000 | R37: 150000 | S37: 113000 | T37: 150000 | U37: 113000 | V37: Cojali Series Integration: PO 0087209779-Q1; PO 0087211879-Q2 | X37: 71813 | Y37: 68872 | AI37: =SUMIF(#REF!,"completed",Table42610[[#This Row],[Act Jan-25]:[Act Dec-25]]) -> #REF! | AJ37: =Table42610[[#This Row],[CF05 C-Hub PF]] -> 150000 | AK37: =SUM(W37:AH38) -> 277605 | AL37: =Table42610[[#This Row],[EAC (based on YTD actuals)]]-Table42610[[#This Row],[BAC (CF05 Plan)]] -> 127605 | AM37: fa
A38: Cojali Development | C38: BM-00110021_002 | E38: ETAS-MSS Cojali | F38: PS-SC/PAC Other Costs | G38: ETAS | H38: Manually added cost | V38: For Actual only, do not plan in MCR | Y38: 9315 | Z38: =127605/3 -> 42535 | AA38: =127605/3 -> 42535 | AB38: =127605/3 -> 42535 | AC38: =$AJ38/12 -> 0 | AD38: =$AJ38/12 -> 0 | AE38: =$AJ38/12 -> 0 | AF38: =$AJ38/12 -> 0 | AG38: =$AJ38/12 -> 0 | AH38: =$AJ38/12 -> 0 | AI38: =SUMIF(#REF!,"completed",Table42610[[#This Row],[Act Jan-25]:[Act Dec-25]]) -> #REF! | AJ38: =Table42610[[#This Row],[CF05 C-Hub PF]] -> 0
A39: Cojali Development | C39: BM-00110021_002 | D39: BM-00110021_002_00000015 | E39: R&D at Cojali | F39: PS-SC/PAC Other Costs | G39: Operation | H39: Other cost | I39: (blank) | J39: other cost | P39: 90000 | Q39: 270000 | R39: 60000 | S39: 300000 | T39: 60000 | U39: 300000 | Y39: =$AJ39/12 -> 5000 | Z39: =$AJ39/12 -> 5000 | AA39: =$AJ39/12 -> 5000 | AB39: =$AJ39/12 -> 5000 | AC39: =$AJ39/12 -> 5000 | AD39: =$AJ39/12 -> 5000 | AE39: =$AJ39/12 -> 5000 | AF39: =$AJ39/12 -> 5000 | ... AH39: =$AJ39/12 -> 5000 | AI39: =SUMIF(#REF!,"completed",Table42610[[#This Row],[Act Jan-25]:[Act Dec-25]]) -> #REF! | AJ39: =Table42610[[#This Row],[CF05 C-Hub PF]] -> 60000 | AK39: =SUM(Table42610[[#This Row],[Act Jan-25]:[Act Dec-25]]) -> 50000 | AL39: =Table42610[[#This Row],[EAC (based on YTD actuals)]]-Table42610[[#This Row],[BAC (CF05 Plan)]] -> -10000
A40: Cojali Development | B40: Premium Multi-Brand Data | C40: BM-00110021_002 | D40: BM-00110021_002_00000016 | E40: PO for Cojali | F40: PS-SC/PAC Other Costs | G40: VCS | H40: Other cost | I40: Scholz, Sebastian | K40: Target resp. | P40: 180000 | Q40: 0 | R40: =Table42610[[#This Row],[C-Hub PF]] -> 180000 | T40: 180000 | V40: 27-Feb: Latest plqnning = 332 kEUR | Y40: 130750 | Z40: 22361.111 | AA40: 22361.111 | AB40: 22361.111 | AC40: 22361.111 | AD40: 22361.111 | AE40: 22361.111 | AF40: 22361.111 | AG40: 22361.111 | AH40: 22361.111 | AI40: =SUMIF(#REF!,"completed",Table42610[[#This Row],[Act Jan-25]:[Act Dec-25]]) -> #REF! | AJ40: =Table42610[[#This Row],[CF05 C-Hub PF]] -> 180000 | AK40: =SUM(W40:AH41) -> 332000 | AL40: =Table42610[[#This Row],[EAC (based on YTD actuals)]]-Table42610[[#This Row],[BAC (CF05 Plan)]] -> 152000
...

Sheet Risk-Tracking
A1: No | B1: Risks | C1: Risk amount(k€) | D1: thereof included in Risk BP26 (BM-00107793_002) | E1: Cost coverage ensured elsewhere | F1: Remaining risk amount | G1: Responsible | H1: Customer | I1: Column1 | J1: Comment Stan | K1: Consider? | L1: Column2 | M1: Hinweis LL | O1: Risks PPT (Mar-26)
A2: 1 | B2: Risk BP26 | C2: 2080 | F2: =C2-D2-E2 -> 2080 | G2: C-Hub Customers | H2: all | O2: Customer integrations | P2: 250
A3: 2 | B3: NA (currently not booking) | C3: 840 | D3: 420 | F3: =C3-D3-E3 -> 420 | G3: C-Hub Product | H3: Penske, Amazon, ViaScience | J3: 9-Mar-26: NA bookings added manually to the Cost tracking | O3: MA for vehicle configuration | P3: 68
A4: 3 | B4: Budget cut CF02 | C4: 400 | F4: =C4-D4-E4 -> 400 | G4: C-Hub Product | O4: NA Team + other cost | P4: 423
A5: 4 | B5: Refunding ögP | C5: 330 | F5: =C5-D5-E5 -> 330 | G5: C-Hub Product | L5: 96 | M5: Planung aktuell Transfer <26 Werte in Diskussion | O5: Operations L1/L2 Incident/Problem/Monitoring | P5: 78
A6: 5 | B6: Risk to overshoot ECP budget beyond ögP funding | C6: 300 | F6: =C6-D6-E6 -> 300 | G6: ECP / PAC2 | I6: see OneNote | L6: 300 | M6: Risiko verstsehe ich nicht ist Kostenneutral ECP Anteil wird von ÖGP bezhalt | O6: Service Operation EU - VI | P6: 100
A7: 6 | B7: Service Improvements (Fleet Session 02.2026) | C7: 230 | F7: =C7-D7-E7 -> 230 | G7: C-Hub Customers | H7: Penske | I7: see OneNote | O7: Service Operation NA - VI | P7: 100
A8: 7 | B8: Manual Monitoring Penske | C8: 50 | D8: 50 | F8: =C8-D8-E8 -> 0 | G8: C-Hub Customers | H8: Penske | I8: see OneNote | O8: Partner Manager | P8: 41
A9: 8 | B9: Unplanned additional effort ViaScience | C9: 100 | F9: =C9-D9-E9 -> 100 | G9: C-Hub Customers | H9: ViaScience | I9: see OneNote | O9: C-Hub XC New Features | P9: 287
A10: 9 | B10: Penske Volume increase (e.g. raw material) | C10: 66 | E10: 66 | F10: =C10-D10-E10 -> 0 | G10: PDCL | H10: Penske | I10: see OneNote | K10: Not concidered | O10: ETAS-MSS Cojali | P10: 113
A11: 10 | B11: SAE Licence | C11: 40 | E11: 40 | F11: =C11-D11-E11 -> 0 | G11: PDCL | H11: Penske | K11: Not concidered | O11: R&D at Cojali | P11: 300
A12: 11 | B12: unplanned effort Heex | C12: 20 | F12: =C12-D12-E12 -> 20 | G12: C-Hub Product / PS-SC/XPS | O12: VCS R&D | P12: 293
A13: 12 | B13: Proprietary CAN Messages Volvo for Remodul | C13: 10 | F13: =C13-D13-E13 -> 10 | G13: C-Hub Product | H13: Remodul | L13: 10 | M13: müsste doch in Remodul rein | O13: Other cost / Lab, HW etc. | P13: 30
A14: 13 | B14: Additional effort WoW | C14: 100 | F14: =C14-D14-E14 -> 100 | G14: C-Hub Product | I14: see OneNote | P14: =SUM(P2:P13) -> 2083
A15: 14 | B15: LTB eMMC | C15: =8*20 -> 160 | F15: =C15-D15-E15 -> 160 | G15: PDCL
A16: 15 | B16: Penske additional effort secure cloud connection | C16: 50 | F16: =C16-D16-E16 -> 50 | G16: C-Hub Product | H16: Penske | I16: see OneNote
A17: 16 | B17: Logistic support C/TMS | C17: 56 | E17: 56 | F17: =C17-D17-E17 -> 0 | G17: PDCL | I17: see OneNote | K17: Not concidered | O17: Refunding ögP | P17: 330
A18: 17 | B18: Operative logistics | C18: 35 | E18: 35 | F18: =C18-D18-E18 -> 0 | G18: PDCL | I18: see OneNote | L18: 35 | M18: muss auf die Logistik Kostenstell | O18: Budget cut CF02 | P18: 400
A19: 18 | B19: additiona MAE invest for higher Penske volume | C19: 10 | F19: =C19-D19-E19 -> 10 | G19: PDCL | K19: Not concidered | O19: ECP | P19: 300
A20: 19 | B20: CARB CTC Certification | C20: 170 | F20: =C20-D20-E20 -> 170 | G20: C-Hub Product | H20: Penske | O20: Service Improvements (Fleet Session xx.02.2026) | P20: 230
A21: 20 | B21: Antenna Homologation | C21: 60 | F21: =C21-D21-E21 -> 60 | G21: C-Hub Customers | H21: Penske | O21: Manual Monitoring Penske | P21: 50
A22: 21 | B22: Mexico Certification | C22: 50 | F22: =C22-D22-E22 -> 50 | G22: C-Hub Customers | H22: new customers | O22: Unplanned additional effort ViaScience | P22: 250
A23: Total | C23: =SUBTOTAL(109,Table10[Risk amount(k€)]) -> 4490 | D23: =SUBTOTAL(109,Table10[thereof included in Risk BP26 (BM-00107793_002)]) -> 470 | E23: =SUBTOTAL(109,Table10[Cost coverage ensured elsewhere]) -> 0 | F23: =SUBTOTAL(109,Table10[Remaining risk amount]) -> 4020 | L23: =SUBTOTAL(109,Table10[Column2]) -> 106 | O23: unplanned effort Heex | P23: 20
C24: =2138462.42211813-2080000 -> 58462.422 | O24: Propietary CAN Messages Volvo for Remodul | P24: 10
O25: Additional effort WoW | P25: 100
C26: =SUM(C2:C22) -> 5157 | D26: =SUM(D2:D25) -> 940 | G26: =C26-D26 -> 4217 | H26: =G26-C10-C11-C17 -> 4055 | J26: =840-420-250 -> 170 | O26: LTB eMMC | P26: =8*20 -> 160
O27: Penske additional effort secure cloud connection | P27: 50
O28: Operative logistics | P28: 35
O29: PPC
C30: =Table10[[#Totals],[Risk amount(k€)]]-D3-D9-D20 -> 4070 | G30: eigene Spalte --> Maßnahme/Finanzierung sichergestellt | O30: CARB CTC Certification | P30: 170
O31: Antenna Homologation | P31: 60
O32: Mexico Certification | P32: 50
P33: =SUM(P17:P32) -> 2215
B34: Bottom-up | C34: 9
B35: first measure to reduce budget demand | D35: -1.5
B36: BP26 pre-steering incl. measures | C36: 7.5
B37: Top down budget cut for BP26 and introduction of risks maintaned in Cust-Proj-Ext MCR plan (xxx) | D37: -2.08
B38: BP26 top-down | C38: 5.5
B39: Top down budget cut for CF02/CF05 | D39: -0.4
B40: CF02 | C40: 5.1
...

Sheet Cost tracking chart
B1: Actuals | C1: Actuals | D1: Prognosis | E1: Prognosis | F1: Prognosis | G1: Prognosis | H1: Prognosis | I1: Prognosis | J1: Prognosis | K1: Prognosis | L1: Prognosis | M1: Prognosis | Q1: Act Mar-25 | R1: Act Apr-25 | S1: Act May-25 | T1: Act Jun-25 | U1: Act Jul-25 | V1: Act Aug-25 | W1: Act Sep-25 | X1: Act Oct-25 | Y1: Act Nov-25 | Z1: Act Dec-25
A2: Cumulative actuals | B2: Jan-26 | C2: Feb-26 | D2: Mar-26 | E2: Apr-26 | F2: May-26 | G2: Jun-26 | H2: Jul-26 | I2: Aug-26 | J2: Sep-26 | K2: Oct-26 | L2: Nov-26 | M2: Dec-26 | Q2: 23333.333 | R2: 23333.333 | S2: 23333.333 | T2: 23333.333 | U2: 23333.333 | V2: 23333.333 | W2: 23333.333 | AA2: =SUM(Q2:Z4) -> 213333.33 | AB2: =AA2/9 -> 23703.704
A3: C-Hub Actuals (BM-00110021_001) | B3: =SUMIF('BP2026_Archive (21Apr26)'!$C:$C,"=BM-00110021_002",'BP2026_Archive (21Apr26)'!W:W)+SUMIF('BP2026_Archive (21Apr26)'!$C:$C,"=BM-00110021_003",'BP2026_Archive (21Apr26)'!W:W)+SUMIF('BP2026_Archive (21Apr26)'!$C:$C,"=BM-00110021_004",'BP2026_Archive (21Apr26)'!W:W)+SUMIF('BP2026_Archive (21Apr26)'!$C:$C,"=BM-00110021_005",'BP2026_Archive (21Apr26)'!W:W)-SUMIF('BP2026_Archive (21Apr26)'!$H:$H,"=Manually added cost",'BP2026_Archive (21Apr26)'!W:W) -> 216492.3 | C3: =Table11[[#This Row],[Jan-26]]+SUMIF('BP2026_Archive (21Apr26)'!$C:$C,"=BM-00110021_002",'BP2026_Archive (21Apr26)'!X:X)+SUMIF('BP2026_Archive (21Apr26)'!$C:$C,"=BM-00110021_003",'BP2026_Archive (21Apr26)'!X:X)+SUMIF('BP2026_Archive (21Apr26)'!$C:$C,"=BM-00110021_004",'BP2026_Archive (21Apr26)'!X:X)+SUMIF('BP2026_Archive (21Apr26)'!$C:$C,"=BM-00110021_005",'BP2026_Archive (21Apr26)'!X:X)-SUMIF('BP2026_Archive (21Apr26)'!$H:$H,"=Manually added cost",'BP2026_Archive (21Apr26)'!X:X) -> 540087.18 | D3: =Table11[[#This Row],[Feb-26]]+SUMIF('BP2026_Archive (21Apr26)'!$C:$C,"=BM-00110021_002",'BP2026_Archive (21Apr26)'!Y:Y)+SUMIF('BP2026_Archive (21Apr26)'!$C:$C,"=BM-00110021_003",'BP2026_Archive (21Apr26)'!Y:Y)+SUMIF('BP2026_Archive (21Apr26)'!$C:$C,"=BM-00110021_004",'BP2026_Archive (21Apr26)'!Y:Y)+SUMIF('BP2026_Archive (21Apr26)'!$C:$C,"=BM-00110021_005",'BP2026_Archive (21Apr26)'!Y:Y)-SUMIF('BP2026_Archive (21Apr26)'!$H:$H,"=Manually added cost",'BP2026_Archive (21Apr26)'!Y:Y) -> 1379756.9 | Q3: 0 | R3: 0 | S3: 0 | T3: 0 | U3: 0 | V3: 0 | W3: 0 | X3: 0 | Y3: 0 | Z3: 0 | AB3: 23703.704
A4: Actuals not yet transferred to MCR | B4: =SUMIF('BP2026_Archive (21Apr26)'!$H:$H,"=Manually added cost",'BP2026_Archive (21Apr26)'!W:W) -> 65439.795 | C4: =Table11[[#This Row],[Jan-26]]+SUMIF('BP2026_Archive (21Apr26)'!$H:$H,"=Manually added cost",'BP2026_Archive (21Apr26)'!X:X) -> 108925.74 | D4: =Table11[[#This Row],[Feb-26]]+SUMIF('BP2026_Archive (21Apr26)'!$H:$H,"=Manually added cost",'BP2026_Archive (21Apr26)'!Y:Y) -> 180226.68 | Q4: 50000
A5: C-Hub All Actuals (incl. not yet transferred) | B5: =SUM(B3:B4) -> 281932.1 | C5: =SUM(C3:C4) -> 649012.92 | D5: =SUM(D3:D4) -> 1559983.5 | E5: =SUM(E3:E4) -> 0 | F5: =SUM(F3:F4) -> 0 | G5: =SUM(G3:G4) -> 0 | H5: =SUM(H3:H4) -> 0 | I5: =SUM(I3:I4) -> 0 | ... M5: =SUM(M3:M4) -> 0 | Q5: =SUM(Q2:Q4) -> 73333.333 | R5: =SUM(R2:R4) -> 23333.333 | S5: =SUM(S2:S4) -> 23333.333 | T5: =SUM(T2:T4) -> 23333.333 | U5: =SUM(U2:U4) -> 23333.333 | V5: =SUM(V2:V4) -> 23333.333 | W5: =SUM(W2:W4) -> 23333.333 | X5: =SUM(X2:X4) -> 0 | ... Z5: =SUM(Z2:Z4) -> 0
A6: Plan CF02 (BM-00110021_001) | B6: =Table11[[#This Row],[Dec-26]]/12 -> 407099.06 | C6: =B6+$M$6/12 -> 814198.12 | D6: =C6+$M$6/12 -> 1221297.2 | E6: =D6+$M$6/12 -> 1628396.2 | F6: =E6+$M$6/12 -> 2035495.3 | G6: =F6+$M$6/12 -> 2442594.4 | H6: =G6+$M$6/12 -> 2849693.4 | I6: =H6+$M$6/12 -> 3256792.5 | J6: =I6+$M$6/12 -> 3663891.5 | ... L6: =K6+$M$6/12 -> 4478089.7 | M6: =Table42610[[#Totals],[BAC (CF05 Plan)]] -> 4885188.7 | Q6: 23703.704 | R6: 23703.704 | S6: 23703.704 | T6: 23703.704 | U6: 23703.704 | V6: 23703.704 | W6: 23703.704 | X6: 23703.704 | Y6: 23703.704
A7: Prognosis 2026 (based on YTD actuals) | E7: =4*Table11[[#This Row],[Dec-26]]/12 -> #REF! | F7: =5*Table11[[#This Row],[Dec-26]]/12 -> #REF! | G7: =6*Table11[[#This Row],[Dec-26]]/12 -> #REF! | H7: =7*Table11[[#This Row],[Dec-26]]/12 -> #REF! | I7: =8*Table11[[#This Row],[Dec-26]]/12 -> #REF! | J7: =9*Table11[[#This Row],[Dec-26]]/12 -> #REF! | K7: =10*Table11[[#This Row],[Dec-26]]/12 -> #REF! | L7: =11*Table11[[#This Row],[Dec-26]]/12 -> #REF! | M7: =Table42610[[#Totals],[EAC (based on YTD actuals)]] -> #REF! | Q7: =Q5-Q6 -> 49629.63 | R7: =R5-R6 -> -370.37037 | S7: =S5-S6 -> -370.37037 | T7: =T5-T6 -> -370.37037 | U7: =U5-U6 -> -370.37037 | V7: =V5-V6 -> -370.37037 | W7: =W5-W6 -> -370.37037 | X7: =X5-X6 -> -23703.704 | ... Z7: =Z5-Z6 -> 0
A8: Gap (Actuals vs Plan), in € | B8: =B5-B6 -> -125166.96 | C8: =C5-C6 -> -165185.2 | D8: =D5-D6 -> 338686.36 | E8: =E5-E6 -> -1628396.2 | F8: =F5-F6 -> -2035495.3 | G8: =G5-G6 -> -2442594.4 | H8: =H5-H6 -> -2849693.4 | I8: =I5-I6 -> -3256792.5 | ... M8: =M5-M6 -> -4885188.7 | Q8: 49629.63 | R8: -370.37037 | S8: -370.37037 | T8: -370.37037 | U8: -370.37037 | V8: -370.37037 | W8: -370.37037 | X8: -23703.704 | Y8: -23703.704 | Z8: 0
A9: Gap (Prognosis vs Plan), in % | B9: =B8/B6 -> -0.30746071 | C9: =C8/C6 -> -0.20288085 | D9: =D8/D6 -> 0.27731691
A10: Customer ext. project (BM-00107793_002) | M10: =Table42610[[#Totals],[CF05 C-Hub Cust Ext]] -> 2070962.4
A11: Financial risks | M11: 700000
M12: =M6+M10+M11 -> 7656151.1
M13: 7848729.1
C14: =C5/2*12 -> 3894077.5
C15: 6200939 | M15: =Table11[[#Totals],[Dec-26]]-M13 -> -192577.98

Sheet Dashboards
A1: New MCR ID | B1: (All)
A3: Task Name (all sub-projects) | B3: Sum of CF05 C-Hub PF | C3: Estimated at completion (Gap as number) | D3: Gap (Prognosis vs. Plan)
A4: Stretch target (budget cut) | B4: -400000 | C4: 0 | D4: 400000
A5: Stretch target XC | B5: -343003.95 | C5: 0 | D5: 343003.95
A6: PO for Cojali | B6: 180000 | C6: 332000 | D6: 152000
A7: VCS R&D | B7: 682500 | C7: 824000 | D7: 141500
A8: ETAS-MSS Cojali | B8: 150000 | C8: 277605 | D8: 127605
A9: E2E System Team - SysArch - Requirements Eng. & System development | B9: 157197.33 | C9: 187708.69 | D9: 30511.36
A10: Customer Cloud Integration / pre-development for VI integration | B10: 78598.667 | C10: 99491.889 | D10: 20893.222
A11: Security Manager | B11: 19649.667 | C11: 29468.335 | D11: 9818.6681
A12: Performing V&V | B12: 81437 | C12: 85415.614 | D12: 3978.6137
A13: Product development lead | B13: 226865.1 | C13: 229309.13 | D13: 2444.026
A14: Service Management | B14: 81435.784 | C14: 83713.807 | D14: 2278.0224
A15: Partner Manager | B15: 40717.892 | C15: 42387.109 | D15: 1669.2169
... A47: Grand Total | B47: 5095188.7 | C47: 5905587.2 | D47: 810398.47
A59: XC only | B59: Sum of CF05 C-Hub PF | C59: Prognosis (based on YTD actuals) | D59: Gap (Porgnosis vs. Plan)
A60: XC | B60: 1362996 | C60: 1545016.3 | D60: 182020.25
A61: C-Hub XC - HW Change for RS-232, K-LINE | B61: 0 | C61: 0 | D61: 0
A62: C-Hub XC New Features | B62: 0 | C62: 0 | D62: 0
A63: C-Hub XC Series Care_004 | B63: 1095000 | C63: 975412.03 | D63: -119587.97
A64: C-Hub XC Series Care_005 | B64: 611000 | C64: 569604.27 | D64: -41395.729
A65: Stretch target XC | B65: -343003.95 | C65: 0 | D65: 343003.95
A66: Grand Total | B66: 1362996 | C66: 1545016.3 | D66: 182020.25
A75: VCS only | B75: Sum of CF05 C-Hub PF | C75: Prognosis (based on YTD actuals) | D75: Gap (Porgnosis vs. Plan)
A76: VCS | B76: 1232500 | C76: 1378000 | D76: 145500
A77: PO for Cojali | B77: 180000 | C77: 332000 | D77: 152000
A78: VCS R&D | B78: 682500 | C78: 824000 | D78: 141500
A79: VCS SW maintance | B79: 370000 | C79: 222000 | D79: -148000
A80: Grand Total | B80: 1232500 | C80: 1378000 | D80: 145500
A87: Cost tracking by "New Team bucket" | B87: Sum of CF05 C-Hub PF | C87: Sum of EAC (based on YTD actuals) | D87: Gap (Porgnosis vs. Plan)
A88: Container App Development | B88: 78598.667 | C88: 66848.141 | D88: -11750.526
A89: HW & BSW | B89: 1706000 | C89: 1545016.3 | D89: -160983.7
A90: NA ENG Team | B90: 423141.91 | C90: 423141.93 | D90: 0.014492754
A91: Partner Management | B91: 40717.892 | C91: 42387.109 | D91: 1669.2169
A92: Premium Multi-Brand Data | B92: 180000 | C92: 332000 | D92: 152000
A93: Refunding | B93: -330000 | C93: -330000 | D93: 0
A94: Service Delivery OPS & Support | B94: 541116.79 | C94: 561572.02 | D94: 20455.224
A95: Stretch target | B95: -743003.95 | C95: 0 | D95: 743003.95
A96: Supporting Functions | B96: 65602.607 | C96: 73933.25 | D96: 8330.6433
A97: Sys-Integration & Testing | B97: 625412.95 | C97: 603310.55 | D97: -22102.399
...

Sheet Final input Arun 002&003
A1: New MCR ID | B1: Task name | C1: Resource group | D1: Orga | E1: Orga new | F1: Cost type | G1: Person booking | H1: Hrs | I1: Amount
A2: BM-00110021_003 | B2: Refunding for C-Hub main project ögP | C2: PS-SC/CE-EU, CE-PE Publicly Funded Project - Refunding | F2: Refunding | G2: (blank) | I2: -330000
A3: BM-00110021_002 | B3: Customer integrations | C3: PS-SC/PAC Other Costs | D3: PA-CS | E3: PA-CS | F3: Other cost | G3: assumtption: 10 customer á 80k€ | I3: 0
A4: BM-00110021_002 | B4: MA for vehicle configuration | C4: PS-SC/PAC Other Costs | D4: ETAS | E4: ETAS | F4: Other cost | G4: Dirk needed for tranfer to PS | I4: 202500
A5: BM-00110021_002 | B5: RM+RD config + Cojali + Pantaris configs | C5: PS-SC/EDS_PS-SC EDS_PS-SC_XPS | D5: Cluj | E5: Cluj | F5: Personnel cost | G5: tbd | H5: 1496 | I5: 78598.667
A6: BM-00110021_002 | B6: RM+RD config + Cojali + Pantaris configs | C6: MS/ECP-PS-IN_iGPM SW-Services_DP | D6: IN | E6: IN | F6: Personnel cost | G6: Dhingra, Manish | H6: 1871 | I6: 52469
A7: BM-00110021_002 | B7: Data / rev. Eng. and AI | C7: PS-SC/PAC Other Costs | D7: PA-CS | E7: PA-CS | F7: Other cost | G7: (blank) | I7: 0
A8: BM-00110021_002 | B8: Series Logistics Concept | C8: PS-SC/PAC Other Costs | D8: M | E8: M | F8: Other cost | G8: (blank) | I8: 0
A9: BM-00110021_002 | B9: NA Team + other cost | C9: PS-SC/EBR-NA SW Eng | D9: PA-CS/NA | E9: PA-CS/NA | F9: Personnel cost | H9: 3720 | I9: 423141.91
A10: BM-00110021_002 | B10: VCS SW maintance | C10: PS-SC/PAC Other Costs | D10: VCS | E10: VCS | F10: Other cost | G10: (blank) | I10: 370000
A11: BM-00110021_002 | B11: System integration and performing V&V | C11: PS-SC/XPS PS-SC XPS development | D11: PA-CS | E11: PA-CS | F11: Personnel cost | G11: Patrick, has not booked yet. | H11: 721 | I11: 124588.8
A12: BM-00110021_002 | B12: Operations L1/L2 Incident/Problem/Monitoring | C12: PS-SC/EDS_PS-SC EDS_PS-SC_XPS | D12: Cluj | E12: Cluj | F12: Personnel cost | G12: Sorina + tbd | H12: 2244 | I12: 117898
A13: BM-00110021_002 | B13: Service Management | C13: PS-SC/ETX | D13: Cluj | E13: Cluj | F13: Personnel cost | G13: Lausch, Ann Kathrin / Cluj PS-SC/ETX | H13: 1550 | I13: 81435.784
A14: BM-00110021_002 | B14: Service Operation EU - VI | C14: PS-SC/PAC Other Costs | D14: Operation | E14: Operation | F14: Other cost? | I14: 50000
A15: BM-00110021_002 | B15: Service Operation NA - VI | C15: PS-SC/PAC Other Costs | D15: Operation | E15: Operation | F15: Other cost? | I15: 50000
A16: BM-00110021_003 | B16: Partner Manager | C16: PS-SC/PAC PAC1 | D16: PA-CS | E16: PA-CS | F16: Personnel cost | G16: Hornung, Floyd? | H16: 283.8 | I16: 42144.3
A17: BM-00110021_002 | B17: EPQ | C17: MS/ECP-PS-IN_iGPM SW-Services_DP | D17: IN | E17: IN | F17: Personnel cost | G17: Lakshmi, Ramakrishnan | H17: 654.85 | I17: 18361.994
A18: BM-00110021_002 | B18: Security Manager | C18: PS-SC/EDS_PS-SC EDS_PS-SC_XPS | D18: Cluj | E18: IN | F18: Personnel cost | G18: Shashikumar, Nagaraju; Khandelwal, Priti | H18: 374 | I18: 19649.667
A19: BM-00110021_002 | B19: Support BGSW (Arun) | C19: MS/END-IN_iGPM Mechanical_Design_Services_W/O_CAD_SW_PS_Sensors | D19: IN | E19: IN | F19: Personnel cost | G19: Palanisamy, Babu | H19: 936 | I19: 19721.52
A20: BM-00110021_002 | B20: BD Support (Technical Documentation) | C20: PS-SC/PAC Other Costs | D20: BD | E20: BD | F20: Other cost | G20: Marianne, Nina | I20: 87000
A21: BM-00110021_003 | B21: Product development lead | C21: PS-CV/EES System Engineer EES (ex CVO/ENP) | D21: CV | E21: CV | F21: Personnel cost | G21: Hodzic, Alkis -> Transfer Alkis to PS-S -> C reduces costs | H21: 1617 | I21: 226865.1
A22: BM-00110021_002 | B22: BD Support (PjM and Controlling) | C22: PS-SC/PAC Other Costs | D22: BD | E22: BD | F22: Other cost | G22: Rainer, Stan | I22: 355125
A23: BM-00110021_002 | B23: CVIT Partner Manager | C23: PS-SC/PAC Other Costs | D23: Bari | E23: Bari | F23: Other cost | G23: (blank) | I23: 98689.339
A24: BM-00110021_002 | B24: ETAS-MSS Cojali | C24: PS-SC/PAC Other Costs | D24: ETAS | E24: ETAS | F24: Other cost | G24: (blank) | I24: 80000
A25: BM-00110021_002 | B25: R&D at Cojali | C25: PS-SC/PAC Other Costs | D25: Operation | E25: Operation | F25: Other cost | G25: (blank) | I25: 90000
A26: BM-00110021_002 | B26: PO for Cojali | C26: PS-SC/PAC Other Costs | D26: VCS | E26: VCS | F26: Other cost | G26: Scholz, Sebastian | I26: 180000
A27: BM-00110021_002 | B27: VCS R&D | C27: PS-SC/PAC Other Costs | D27: VCS | E27: VCS | F27: Other cost | G27: (blank) | I27: 682500
A28: BM-00110021_002 | B28: BD Support (Cojali & CDK) | C28: PS-SC/PAC Other Costs | D28: BD | E28: BD | F28: Other cost | G28: Gibayev Oleg | I28: 136028.67
A29: BM-00110021_003 | B29: CDK development | C29: PS-SC/EDS_PS-SC EDS_PS-SC_XPS | D29: Cluj | E29: Cluj | F29: Personnel cost | G29: tbd | H29: 1496 | I29: 78598.667
A30: BM-00110021_002 | B30: Technical Docu Cluj | C30: PS-SC/EDS_PS-SC EDS_PS-SC_XPS | D30: Cluj | E30: Cluj | F30: Personnel cost | G30: tbd | H30: 748 | I30: 39299.333
A31: BM-00110021_003 | B31: Other cost / Lab, HW etc. | C31: PS-SC/PAC Other Costs | D31: Operation | E31: Operation | F31: Other cost | G31: (blank) | I31: 20000
A32: BM-00110021_002 | B32: Customer Cloud Integration / pre-development for VI integration | C32: PS-SC/EDS_PS-SC EDS_PS-SC_XPS | D32: Cluj | E32: Cluj | F32: Personnel cost | G32: Modoc, Daniel Stefan | H32: 1496 | I32: 78598.667
A33: BM-00110021_002 | B33: E2E System Team - Requirements Eng. & System development | C33: MS/ECP-PS-IN_iGPM SW-Services_DP | D33: IN | E33: IN | F33: Personnel cost | G33: Praveen, K M | H33: 1871 | I33: 52462.84
A34: BM-00110021_002 | B34: E2E System Team - SysArch - Requirements Eng. & System development | C34: PS-SC/EDS_PS-SC EDS_PS-SC_XPS | D34: Cluj | E34: Cluj | F34: Personnel cost | G34: Guias, Cornel Liviu; Hategan, Liviu Ioan; | H34: 2992 | I34: 157197.33
A35: BM-00110021_002 | B35: System integration and performing V&V | C35: PS-CV/EES System Engineer EES (ex CVO/ENP) | D35: CV | E35: CV | F35: Personnel cost | G35: Blohm, Christina; Frank, Kornelius | H35: 511.65869 | I35: 71785.714
A36: BM-00110021_003 | B36: System Integration and Solution Architecture technical customer support | C36: PS-SC/PAC PAC1 | D36: PA-CS | E36: PA-CS | F36: Personnel cost | G36: Perless, Alexander | H36: 1419 | I36: 210721.5
A37: BM-00110021_002 | B37: Managing V&V | C37: PS-SC/ETX V&V CE Other Cust. Proj. | D37: Cluj | E37: Cluj | F37: Personnel cost | G37: Fagarasi, Lorand | H37: 1550 | I37: 81437
A38: BM-00110021_002 | B38: Performing V&V | C38: PS-SC/ETX V&V CE Other Cust. Proj. | D38: Cluj | E38: Cluj | F38: Personnel cost | G38: Chirlejan, Alex Bogdan | H38: 1550 | I38: 81437
A39: BM-00110021_002 | B39: Installation App development | C39: PS-SC/PAC Other Costs | D39: Operation | E39: Operation | F39: Other cost | I39: 0
A40: C-Hub Cust Ext - BM-00107793_002 | B40: Customer integrations | C40: PS-SC/PAC Other Costs | D40: PA-CS | E40: PA-CS | F40: Other cost | G40: assumtption: 10 customer á 80k€ | I40: 250000
...

Sheet XC-fix
B4: green
B5: =SUM(A6:A9) -> 1364375
A6: 626875
A7: 626875
A8: 55312.5
A9: 55312.5
A11: BM-number | B11: Task | C11: C-Hub PF | D11: C-Hub Cust Ext
A12: 004 | B12: various (see Can's planning) | C12: 940241.92
A13: xxx | B13: XC-CP Customer Extention (other cost) | D13: =C14*-1 -> 286993.92
A14: 004 | B14: Stretch target (other cost) | C14: -286993.92
A15: 005 | B15: various (see Can's planning) | C15: 711127
C16: =SUM(C12:C15) -> 1364375
C19: 1588006.1 | D19: =C16+D13-C19 -> 63362.84
D22: 63362.84
B27: =C27/$C$34 -> 0.32340436 | C27: =(1475000*0.85)/2 -> 626875 | D27: =B27*$C$37 -> -92815.086 | E27: =C27+D27 -> 534059.91
B28: =C28/$C$34 -> 0.32340436 | C28: =(1475000*0.85)/2 -> 626875 | D28: =B28*$C$37 -> -92815.086 | E28: =C28+D28 -> 534059.91
